2024-03-18 16:48:11,335 [INFO]: 2024-03-18 16:48:11.335764 - 'Ahalogist_cases/test_login.py::TestLogin::test_login_page' finished with outcome: passed
2024-03-18 16:48:51,685 [INFO]: 2024-03-18 16:48:51.685818 - 'Ahalogist_cases/test_performance.py::Test_performance::test_performance_influence' finished with outcome: passed
2024-03-18 16:50:24,106 [INFO]: 2024-03-18 16:50:24.106067 - 'Ahalogist_cases/test_login.py::TestLogin::test_login_page' finished with outcome: passed
2024-03-18 16:51:01,994 [INFO]: 2024-03-18 16:51:01.994033 - 'Ahalogist_cases/test_performance.py::Test_performance::test_performance_influence' finished with outcome: passed
2024-03-18 20:39:15,455 [INFO]: 2024-03-18 - 'Influencers_cases/test_login.py::Test_login::test_login_page' finished with outcome: passed
2024-03-18 20:39:49,186 [INFO]: 2024-03-18 - 'Influencers_cases/test_signup.py::Test_Signup::test_random_email' finished with outcome: passed
2024-03-18 20:40:13,964 [INFO]: 2024-03-18 - 'Influencers_cases/test_signup.py::Test_Signup::test_form_child' finished with outcome: passed
2024-03-18 20:40:26,736 [INFO]: 2024-03-18 - 'Influencers_cases/test_signup.py::Test_Signup::test_verification_email' finished with outcome: passed
2024-03-18 20:40:47,484 [INFO]: 2024-03-18 - 'Influencers_cases/test_login.py::Test_login::test_login_page' finished with outcome: passed
2024-03-18 20:41:02,015 [INFO]: 2024-03-18 - 'Influencers_cases/test_general_pages.py::Test_Home::test_influences_profile_setting' finished with outcome: passed
2024-03-18 20:41:22,454 [WARNING]: Retrying (Retry(total=2, connect=None, read=None, redirect=None, status=None)) after connection broken by 'NewConnectionError('<urllib3.connection.HTTPConnection object at 0x7f9bb8e183d0>: Failed to establish a new connection: [Errno 61] Connection refused')': /session/33529143541b05c0df23c1e9aa2857af
2024-03-18 20:41:22,456 [WARNING]: Retrying (Retry(total=1, connect=None, read=None, redirect=None, status=None)) after connection broken by 'NewConnectionError('<urllib3.connection.HTTPConnection object at 0x7f9bb921d2e0>: Failed to establish a new connection: [Errno 61] Connection refused')': /session/33529143541b05c0df23c1e9aa2857af
2024-03-18 20:41:22,458 [WARNING]: Retrying (Retry(total=0, connect=None, read=None, redirect=None, status=None)) after connection broken by 'NewConnectionError('<urllib3.connection.HTTPConnection object at 0x7f9bb921d0a0>: Failed to establish a new connection: [Errno 61] Connection refused')': /session/33529143541b05c0df23c1e9aa2857af
2024-03-19 15:50:26,415 [WARNING]: Retrying (Retry(total=2, connect=None, read=None, redirect=None, status=None)) after connection broken by 'NewConnectionError('<urllib3.connection.HTTPConnection object at 0x7fe2d50d7610>: Failed to establish a new connection: [Errno 61] Connection refused')': /session/7e53ce10034a9080d11124c7554ec215
2024-03-19 15:50:26,431 [WARNING]: Retrying (Retry(total=1, connect=None, read=None, redirect=None, status=None)) after connection broken by 'NewConnectionError('<urllib3.connection.HTTPConnection object at 0x7fe2d50d7460>: Failed to establish a new connection: [Errno 61] Connection refused')': /session/7e53ce10034a9080d11124c7554ec215
2024-03-19 15:50:26,436 [WARNING]: Retrying (Retry(total=0, connect=None, read=None, redirect=None, status=None)) after connection broken by 'NewConnectionError('<urllib3.connection.HTTPConnection object at 0x7fe2d50d76d0>: Failed to establish a new connection: [Errno 61] Connection refused')': /session/7e53ce10034a9080d11124c7554ec215
2024-03-19 15:52:47,026 [INFO]: 2024-03-19 - 'Influencers_cases/test_login.py::Test_login::test_login_page' finished with outcome: passed
2024-03-19 15:52:59,780 [INFO]: 2024-03-19 - 'Influencers_cases/test_general_pages.py::Test_Home::test_influences_profile_setting' finished with outcome: passed
2024-03-19 15:53:19,589 [INFO]: 2024-03-19 - 'Influencers_cases/csdcnlsdknvtest_socail_pages.py::Test_Social::test_pinterest_author' finished with outcome: passed
2024-03-19 15:53:33,901 [INFO]: 2024-03-19 - 'Influencers_cases/csdcnlsdknvtest_socail_pages.py::Test_Social::test_facebook_author' finished with outcome: passed
2024-03-19 15:54:23,052 [ERROR]: 2024-03-19 - 'Influencers_cases/csdcnlsdknvtest_socail_pages.py::Test_Social::test_instagram_author' finished with outcome: failed
2024-03-19 15:54:25,253 [INFO]: 2024-03-19 - 'Influencers_cases/csdcnlsdknvtest_socail_pages.py::Test_Social::test_next_button' finished with outcome: passed
2024-03-19 15:54:40,773 [INFO]: 2024-03-19 - 'Influencers_cases/test_creator_details.py::Test_Creator::test_creator_details' finished with outcome: passed
2024-03-19 15:54:51,814 [INFO]: 2024-03-19 - 'Influencers_cases/test_compensation.py::Test_Compensation::test_compensation_details' finished with outcome: passed
2024-03-19 15:55:08,473 [INFO]: 2024-03-19 - 'Influencers_cases/test_capabilities.py::Test_Capabilities::test_capabilities_details' finished with outcome: passed
2024-03-19 15:55:16,496 [INFO]: 2024-03-19 - 'Influencers_cases/test_personal_details.py::Test_Personal::test_personal_details' finished with outcome: passed
2024-03-19 15:55:37,874 [WARNING]: Retrying (Retry(total=2, connect=None, read=None, redirect=None, status=None)) after connection broken by 'NewConnectionError('<urllib3.connection.HTTPConnection object at 0x7fefd4f18b50>: Failed to establish a new connection: [Errno 61] Connection refused')': /session/ff85343c09dd4b4f0e1b66fb4f20a3d1
2024-03-19 15:55:37,876 [WARNING]: Retrying (Retry(total=1, connect=None, read=None, redirect=None, status=None)) after connection broken by 'NewConnectionError('<urllib3.connection.HTTPConnection object at 0x7fefd5361a90>: Failed to establish a new connection: [Errno 61] Connection refused')': /session/ff85343c09dd4b4f0e1b66fb4f20a3d1
2024-03-19 15:55:37,878 [WARNING]: Retrying (Retry(total=0, connect=None, read=None, redirect=None, status=None)) after connection broken by 'NewConnectionError('<urllib3.connection.HTTPConnection object at 0x7fefd528d3a0>: Failed to establish a new connection: [Errno 61] Connection refused')': /session/ff85343c09dd4b4f0e1b66fb4f20a3d1
2024-03-26 22:35:48,154 [WARNING]: Retrying (Retry(total=2, connect=None, read=None, redirect=None, status=None)) after connection broken by 'NewConnectionError('<urllib3.connection.HTTPConnection object at 0x7f9496f12550>: Failed to establish a new connection: [Errno 61] Connection refused')': /session/736369fa355a6a79da6771dc563721a0
2024-03-26 22:35:48,158 [WARNING]: Retrying (Retry(total=1, connect=None, read=None, redirect=None, status=None)) after connection broken by 'NewConnectionError('<urllib3.connection.HTTPConnection object at 0x7f9497031820>: Failed to establish a new connection: [Errno 61] Connection refused')': /session/736369fa355a6a79da6771dc563721a0
2024-03-26 22:35:48,160 [WARNING]: Retrying (Retry(total=0, connect=None, read=None, redirect=None, status=None)) after connection broken by 'NewConnectionError('<urllib3.connection.HTTPConnection object at 0x7f9497031940>: Failed to establish a new connection: [Errno 61] Connection refused')': /session/736369fa355a6a79da6771dc563721a0
2024-03-26 22:45:31,068 [INFO]: 2024-03-26 - 'Influencers_cases/test_login.py::Test_login::test_login_page' finished with outcome: passed
2024-03-26 22:45:45,145 [INFO]: 2024-03-26 - 'Influencers_cases/test_general_pages.py::Test_Home::test_influences_profile_setting' finished with outcome: passed
2024-03-26 22:46:08,221 [INFO]: 2024-03-26 - 'Influencers_cases/csdcnlsdknvtest_socail_pages.py::Test_Social::test_pinterest_author' finished with outcome: passed
2024-03-26 22:46:24,860 [INFO]: 2024-03-26 - 'Influencers_cases/csdcnlsdknvtest_socail_pages.py::Test_Social::test_facebook_author' finished with outcome: passed
2024-03-26 22:47:18,026 [ERROR]: 2024-03-26 - 'Influencers_cases/csdcnlsdknvtest_socail_pages.py::Test_Social::test_instagram_author' finished with outcome: failed
2024-03-26 22:47:20,302 [INFO]: 2024-03-26 - 'Influencers_cases/csdcnlsdknvtest_socail_pages.py::Test_Social::test_next_button' finished with outcome: passed
2024-03-26 22:47:35,584 [INFO]: 2024-03-26 - 'Influencers_cases/test_creator_details.py::Test_Creator::test_creator_details' finished with outcome: passed
2024-03-26 22:47:47,527 [INFO]: 2024-03-26 - 'Influencers_cases/test_compensation.py::Test_Compensation::test_compensation_details' finished with outcome: passed
2024-03-26 22:48:04,445 [INFO]: 2024-03-26 - 'Influencers_cases/test_capabilities.py::Test_Capabilities::test_capabilities_details' finished with outcome: passed
2024-03-26 22:48:11,902 [ERROR]: 2024-03-26 - 'Influencers_cases/test_personal_details.py::Test_Personal::test_personal_details' finished with outcome: failed
2024-03-26 22:48:27,069 [INFO]: 2024-03-26 - 'Influencers_cases/test_application.py::Test_Application::test_application' finished with outcome: passed
2024-03-26 22:48:30,840 [WARNING]: Retrying (Retry(total=2, connect=None, read=None, redirect=None, status=None)) after connection broken by 'NewConnectionError('<urllib3.connection.HTTPConnection object at 0x7fb637711820>: Failed to establish a new connection: [Errno 61] Connection refused')': /session/252146de14c4722065e88ef9f1ab2718
2024-03-26 22:48:30,841 [WARNING]: Retrying (Retry(total=1, connect=None, read=None, redirect=None, status=None)) after connection broken by 'NewConnectionError('<urllib3.connection.HTTPConnection object at 0x7fb637b1a130>: Failed to establish a new connection: [Errno 61] Connection refused')': /session/252146de14c4722065e88ef9f1ab2718
2024-03-26 22:48:30,845 [WARNING]: Retrying (Retry(total=0, connect=None, read=None, redirect=None, status=None)) after connection broken by 'NewConnectionError('<urllib3.connection.HTTPConnection object at 0x7fb637a0f8e0>: Failed to establish a new connection: [Errno 61] Connection refused')': /session/252146de14c4722065e88ef9f1ab2718
2024-03-27 02:42:03,958 [INFO]: 2024-03-27 - 'Influencers_cases/test_login.py::Test_login::test_login_page' finished with outcome: passed
2024-03-27 02:42:17,406 [INFO]: 2024-03-27 - 'Influencers_cases/test_general_pages.py::Test_Home::test_influences_profile_setting' finished with outcome: passed
2024-03-27 02:42:39,131 [INFO]: 2024-03-27 - 'Influencers_cases/csdcnlsdknvtest_socail_pages.py::Test_Social::test_pinterest_author' finished with outcome: passed
2024-03-27 02:42:55,209 [INFO]: 2024-03-27 - 'Influencers_cases/csdcnlsdknvtest_socail_pages.py::Test_Social::test_facebook_author' finished with outcome: passed
2024-03-27 02:43:46,094 [ERROR]: 2024-03-27 - 'Influencers_cases/csdcnlsdknvtest_socail_pages.py::Test_Social::test_instagram_author' finished with outcome: failed
2024-03-27 02:43:48,306 [INFO]: 2024-03-27 - 'Influencers_cases/csdcnlsdknvtest_socail_pages.py::Test_Social::test_next_button' finished with outcome: passed
2024-03-27 02:44:04,137 [INFO]: 2024-03-27 - 'Influencers_cases/test_creator_details.py::Test_Creator::test_creator_details' finished with outcome: passed
2024-03-27 02:44:15,275 [INFO]: 2024-03-27 - 'Influencers_cases/test_compensation.py::Test_Compensation::test_compensation_details' finished with outcome: passed
2024-03-27 02:44:32,633 [INFO]: 2024-03-27 - 'Influencers_cases/test_capabilities.py::Test_Capabilities::test_capabilities_details' finished with outcome: passed
2024-03-27 02:45:09,087 [ERROR]: 2024-03-27 - 'Influencers_cases/test_personal_details.py::Test_Personal::test_personal_details' finished with outcome: failed
2024-03-27 02:45:12,984 [WARNING]: Retrying (Retry(total=2, connect=None, read=None, redirect=None, status=None)) after connection broken by 'NewConnectionError('<urllib3.connection.HTTPConnection object at 0x7fd8155d0820>: Failed to establish a new connection: [Errno 61] Connection refused')': /session/8140908c84afaf155820b03f632259f2
2024-03-27 02:45:12,986 [WARNING]: Retrying (Retry(total=1, connect=None, read=None, redirect=None, status=None)) after connection broken by 'NewConnectionError('<urllib3.connection.HTTPConnection object at 0x7fd813627070>: Failed to establish a new connection: [Errno 61] Connection refused')': /session/8140908c84afaf155820b03f632259f2
2024-03-27 02:45:12,988 [WARNING]: Retrying (Retry(total=0, connect=None, read=None, redirect=None, status=None)) after connection broken by 'NewConnectionError('<urllib3.connection.HTTPConnection object at 0x7fd812bfdf40>: Failed to establish a new connection: [Errno 61] Connection refused')': /session/8140908c84afaf155820b03f632259f2
2024-03-27 02:49:38,855 [INFO]: 2024-03-27 - 'Influencers_cases/test_login.py::Test_login::test_login_page' finished with outcome: passed
2024-03-27 02:49:53,428 [INFO]: 2024-03-27 - 'Influencers_cases/test_general_pages.py::Test_Home::test_influences_profile_setting' finished with outcome: passed
2024-03-27 02:50:16,040 [INFO]: 2024-03-27 - 'Influencers_cases/csdcnlsdknvtest_socail_pages.py::Test_Social::test_pinterest_author' finished with outcome: passed
2024-03-27 02:50:32,231 [INFO]: 2024-03-27 - 'Influencers_cases/csdcnlsdknvtest_socail_pages.py::Test_Social::test_facebook_author' finished with outcome: passed
2024-03-27 02:51:20,042 [ERROR]: 2024-03-27 - 'Influencers_cases/csdcnlsdknvtest_socail_pages.py::Test_Social::test_instagram_author' finished with outcome: failed
2024-03-27 02:51:22,204 [INFO]: 2024-03-27 - 'Influencers_cases/csdcnlsdknvtest_socail_pages.py::Test_Social::test_next_button' finished with outcome: passed
2024-03-27 02:51:36,918 [INFO]: 2024-03-27 - 'Influencers_cases/test_creator_details.py::Test_Creator::test_creator_details' finished with outcome: passed
2024-03-27 02:51:48,180 [INFO]: 2024-03-27 - 'Influencers_cases/test_compensation.py::Test_Compensation::test_compensation_details' finished with outcome: passed
2024-03-27 02:52:04,490 [INFO]: 2024-03-27 - 'Influencers_cases/test_capabilities.py::Test_Capabilities::test_capabilities_details' finished with outcome: passed
2024-03-27 02:52:41,211 [ERROR]: 2024-03-27 - 'Influencers_cases/test_personal_details.py::Test_Personal::test_personal_details' finished with outcome: failed
2024-03-27 02:52:55,726 [WARNING]: Retrying (Retry(total=2, connect=None, read=None, redirect=None, status=None)) after connection broken by 'NewConnectionError('<urllib3.connection.HTTPConnection object at 0x7f786ef122e0>: Failed to establish a new connection: [Errno 61] Connection refused')': /session/41216ceeaa0084d9ba3cc39c48a81f1d
2024-03-27 02:52:55,728 [WARNING]: Retrying (Retry(total=1, connect=None, read=None, redirect=None, status=None)) after connection broken by 'NewConnectionError('<urllib3.connection.HTTPConnection object at 0x7f786f4260d0>: Failed to establish a new connection: [Errno 61] Connection refused')': /session/41216ceeaa0084d9ba3cc39c48a81f1d
2024-03-27 02:52:55,729 [WARNING]: Retrying (Retry(total=0, connect=None, read=None, redirect=None, status=None)) after connection broken by 'NewConnectionError('<urllib3.connection.HTTPConnection object at 0x7f786f2ddee0>: Failed to establish a new connection: [Errno 61] Connection refused')': /session/41216ceeaa0084d9ba3cc39c48a81f1d
2024-03-27 02:54:49,830 [INFO]: 2024-03-27 - 'Influencers_cases/test_login.py::Test_login::test_login_page' finished with outcome: passed
2024-03-27 02:55:04,546 [INFO]: 2024-03-27 - 'Influencers_cases/test_general_pages.py::Test_Home::test_influences_profile_setting' finished with outcome: passed
2024-03-27 02:55:28,190 [INFO]: 2024-03-27 - 'Influencers_cases/csdcnlsdknvtest_socail_pages.py::Test_Social::test_pinterest_author' finished with outcome: passed
2024-03-27 02:55:43,546 [INFO]: 2024-03-27 - 'Influencers_cases/csdcnlsdknvtest_socail_pages.py::Test_Social::test_facebook_author' finished with outcome: passed
2024-03-27 02:56:32,677 [ERROR]: 2024-03-27 - 'Influencers_cases/csdcnlsdknvtest_socail_pages.py::Test_Social::test_instagram_author' finished with outcome: failed
2024-03-27 02:56:34,919 [INFO]: 2024-03-27 - 'Influencers_cases/csdcnlsdknvtest_socail_pages.py::Test_Social::test_next_button' finished with outcome: passed
2024-03-27 02:56:49,522 [INFO]: 2024-03-27 - 'Influencers_cases/test_creator_details.py::Test_Creator::test_creator_details' finished with outcome: passed
2024-03-27 02:57:00,744 [INFO]: 2024-03-27 - 'Influencers_cases/test_compensation.py::Test_Compensation::test_compensation_details' finished with outcome: passed
2024-03-27 02:57:18,082 [INFO]: 2024-03-27 - 'Influencers_cases/test_capabilities.py::Test_Capabilities::test_capabilities_details' finished with outcome: passed
2024-03-27 02:57:34,129 [WARNING]: Retrying (Retry(total=2, connect=None, read=None, redirect=None, status=None)) after connection broken by 'NewConnectionError('<urllib3.connection.HTTPConnection object at 0x7fe97ddd3820>: Failed to establish a new connection: [Errno 61] Connection refused')': /session/79851f9d4c0599ab7c4450c603bd17c3
2024-03-27 02:57:34,131 [WARNING]: Retrying (Retry(total=1, connect=None, read=None, redirect=None, status=None)) after connection broken by 'NewConnectionError('<urllib3.connection.HTTPConnection object at 0x7fe97e2673d0>: Failed to establish a new connection: [Errno 61] Connection refused')': /session/79851f9d4c0599ab7c4450c603bd17c3
2024-03-27 02:57:34,133 [WARNING]: Retrying (Retry(total=0, connect=None, read=None, redirect=None, status=None)) after connection broken by 'NewConnectionError('<urllib3.connection.HTTPConnection object at 0x7fe97e0a7eb0>: Failed to establish a new connection: [Errno 61] Connection refused')': /session/79851f9d4c0599ab7c4450c603bd17c3
2024-03-27 02:59:02,692 [INFO]: 2024-03-27 - 'Influencers_cases/test_login.py::Test_login::test_login_page' finished with outcome: passed
2024-03-27 02:59:15,686 [INFO]: 2024-03-27 - 'Influencers_cases/test_general_pages.py::Test_Home::test_influences_profile_setting' finished with outcome: passed
2024-03-27 02:59:38,462 [INFO]: 2024-03-27 - 'Influencers_cases/csdcnlsdknvtest_socail_pages.py::Test_Social::test_pinterest_author' finished with outcome: passed
2024-03-27 02:59:54,816 [INFO]: 2024-03-27 - 'Influencers_cases/csdcnlsdknvtest_socail_pages.py::Test_Social::test_facebook_author' finished with outcome: passed
2024-03-27 03:00:42,889 [ERROR]: 2024-03-27 - 'Influencers_cases/csdcnlsdknvtest_socail_pages.py::Test_Social::test_instagram_author' finished with outcome: failed
2024-03-27 03:00:45,098 [INFO]: 2024-03-27 - 'Influencers_cases/csdcnlsdknvtest_socail_pages.py::Test_Social::test_next_button' finished with outcome: passed
2024-03-27 03:01:00,721 [INFO]: 2024-03-27 - 'Influencers_cases/test_creator_details.py::Test_Creator::test_creator_details' finished with outcome: passed
2024-03-27 03:01:12,347 [INFO]: 2024-03-27 - 'Influencers_cases/test_compensation.py::Test_Compensation::test_compensation_details' finished with outcome: passed
2024-03-27 03:01:29,217 [INFO]: 2024-03-27 - 'Influencers_cases/test_capabilities.py::Test_Capabilities::test_capabilities_details' finished with outcome: passed
2024-03-27 03:02:05,185 [ERROR]: 2024-03-27 - 'Influencers_cases/test_personal_details.py::Test_Personal::test_personal_details' finished with outcome: failed
2024-03-27 03:02:09,747 [WARNING]: Retrying (Retry(total=2, connect=None, read=None, redirect=None, status=None)) after connection broken by 'NewConnectionError('<urllib3.connection.HTTPConnection object at 0x7fd3345ee130>: Failed to establish a new connection: [Errno 61] Connection refused')': /session/1406bb7142937ec2bcd1259583d855a5
2024-03-27 03:02:09,749 [WARNING]: Retrying (Retry(total=1, connect=None, read=None, redirect=None, status=None)) after connection broken by 'NewConnectionError('<urllib3.connection.HTTPConnection object at 0x7fd331c31160>: Failed to establish a new connection: [Errno 61] Connection refused')': /session/1406bb7142937ec2bcd1259583d855a5
2024-03-27 03:02:09,750 [WARNING]: Retrying (Retry(total=0, connect=None, read=None, redirect=None, status=None)) after connection broken by 'NewConnectionError('<urllib3.connection.HTTPConnection object at 0x7fd334a4bca0>: Failed to establish a new connection: [Errno 61] Connection refused')': /session/1406bb7142937ec2bcd1259583d855a5
2024-03-27 03:04:16,016 [INFO]: 2024-03-27 - 'Influencers_cases/test_login.py::Test_login::test_login_page' finished with outcome: passed
2024-03-27 03:04:28,013 [INFO]: 2024-03-27 - 'Influencers_cases/test_general_pages.py::Test_Home::test_influences_profile_setting' finished with outcome: passed
2024-03-27 03:04:46,588 [INFO]: 2024-03-27 - 'Influencers_cases/csdcnlsdknvtest_socail_pages.py::Test_Social::test_pinterest_author' finished with outcome: passed
2024-03-27 03:05:00,549 [INFO]: 2024-03-27 - 'Influencers_cases/csdcnlsdknvtest_socail_pages.py::Test_Social::test_facebook_author' finished with outcome: passed
2024-03-27 03:05:48,870 [ERROR]: 2024-03-27 - 'Influencers_cases/csdcnlsdknvtest_socail_pages.py::Test_Social::test_instagram_author' finished with outcome: failed
2024-03-27 03:05:50,480 [INFO]: 2024-03-27 - 'Influencers_cases/csdcnlsdknvtest_socail_pages.py::Test_Social::test_next_button' finished with outcome: passed
2024-03-27 03:06:03,336 [INFO]: 2024-03-27 - 'Influencers_cases/test_creator_details.py::Test_Creator::test_creator_details' finished with outcome: passed
2024-03-27 03:06:14,596 [INFO]: 2024-03-27 - 'Influencers_cases/test_compensation.py::Test_Compensation::test_compensation_details' finished with outcome: passed
2024-03-27 03:06:30,932 [INFO]: 2024-03-27 - 'Influencers_cases/test_capabilities.py::Test_Capabilities::test_capabilities_details' finished with outcome: passed
2024-03-27 03:07:06,901 [ERROR]: 2024-03-27 - 'Influencers_cases/test_personal_details.py::Test_Personal::test_personal_details' finished with outcome: failed
2024-03-27 03:07:09,939 [WARNING]: Retrying (Retry(total=2, connect=None, read=None, redirect=None, status=None)) after connection broken by 'NewConnectionError('<urllib3.connection.HTTPConnection object at 0x7f8daa135190>: Failed to establish a new connection: [Errno 61] Connection refused')': /session/b0b68d7ee605e3393877dafc74dffa3e
2024-03-27 03:07:09,941 [WARNING]: Retrying (Retry(total=1, connect=None, read=None, redirect=None, status=None)) after connection broken by 'NewConnectionError('<urllib3.connection.HTTPConnection object at 0x7f8daa135880>: Failed to establish a new connection: [Errno 61] Connection refused')': /session/b0b68d7ee605e3393877dafc74dffa3e
2024-03-27 03:07:09,942 [WARNING]: Retrying (Retry(total=0, connect=None, read=None, redirect=None, status=None)) after connection broken by 'NewConnectionError('<urllib3.connection.HTTPConnection object at 0x7f8da7473ee0>: Failed to establish a new connection: [Errno 61] Connection refused')': /session/b0b68d7ee605e3393877dafc74dffa3e
2024-03-27 03:08:42,997 [ERROR]: 2024-03-27 - 'Influencers_cases/test_login.py::Test_login::test_login_page' finished with outcome: failed
2024-03-27 03:08:47,153 [ERROR]: 2024-03-27 - 'Influencers_cases/test_general_pages.py::Test_Home::test_influences_profile_setting' finished with outcome: failed
2024-03-27 03:09:15,610 [WARNING]: Retrying (Retry(total=2, connect=None, read=None, redirect=None, status=None)) after connection broken by 'NewConnectionError('<urllib3.connection.HTTPConnection object at 0x7fb3c4f149d0>: Failed to establish a new connection: [Errno 61] Connection refused')': /session/e8a973d68fb2934f9fa086532a1cad25
2024-03-27 03:09:15,612 [WARNING]: Retrying (Retry(total=1, connect=None, read=None, redirect=None, status=None)) after connection broken by 'NewConnectionError('<urllib3.connection.HTTPConnection object at 0x7fb3c545f5b0>: Failed to establish a new connection: [Errno 61] Connection refused')': /session/e8a973d68fb2934f9fa086532a1cad25
2024-03-27 03:09:15,613 [WARNING]: Retrying (Retry(total=0, connect=None, read=None, redirect=None, status=None)) after connection broken by 'NewConnectionError('<urllib3.connection.HTTPConnection object at 0x7fb3c545f460>: Failed to establish a new connection: [Errno 61] Connection refused')': /session/e8a973d68fb2934f9fa086532a1cad25
2024-03-27 03:09:51,564 [INFO]: 2024-03-27 - 'Influencers_cases/test_login.py::Test_login::test_login_page' finished with outcome: passed
2024-03-27 03:10:04,213 [INFO]: 2024-03-27 - 'Influencers_cases/test_general_pages.py::Test_Home::test_influences_profile_setting' finished with outcome: passed
2024-03-27 03:10:23,913 [INFO]: 2024-03-27 - 'Influencers_cases/csdcnlsdknvtest_socail_pages.py::Test_Social::test_pinterest_author' finished with outcome: passed
2024-03-27 03:10:38,134 [INFO]: 2024-03-27 - 'Influencers_cases/csdcnlsdknvtest_socail_pages.py::Test_Social::test_facebook_author' finished with outcome: passed
2024-03-27 03:11:25,486 [ERROR]: 2024-03-27 - 'Influencers_cases/csdcnlsdknvtest_socail_pages.py::Test_Social::test_instagram_author' finished with outcome: failed
2024-03-27 03:11:26,962 [INFO]: 2024-03-27 - 'Influencers_cases/csdcnlsdknvtest_socail_pages.py::Test_Social::test_next_button' finished with outcome: passed
2024-03-27 03:11:38,961 [INFO]: 2024-03-27 - 'Influencers_cases/test_creator_details.py::Test_Creator::test_creator_details' finished with outcome: passed
2024-03-27 03:11:49,184 [INFO]: 2024-03-27 - 'Influencers_cases/test_compensation.py::Test_Compensation::test_compensation_details' finished with outcome: passed
2024-03-27 03:12:05,454 [INFO]: 2024-03-27 - 'Influencers_cases/test_capabilities.py::Test_Capabilities::test_capabilities_details' finished with outcome: passed
2024-03-27 03:12:41,420 [ERROR]: 2024-03-27 - 'Influencers_cases/test_personal_details.py::Test_Personal::test_personal_details' finished with outcome: failed
2024-03-27 03:12:48,767 [WARNING]: Retrying (Retry(total=2, connect=None, read=None, redirect=None, status=None)) after connection broken by 'NewConnectionError('<urllib3.connection.HTTPConnection object at 0x7f97fb814a30>: Failed to establish a new connection: [Errno 61] Connection refused')': /session/dd68689530806d5cce215faad14b5f22
2024-03-27 03:12:48,769 [WARNING]: Retrying (Retry(total=1, connect=None, read=None, redirect=None, status=None)) after connection broken by 'NewConnectionError('<urllib3.connection.HTTPConnection object at 0x7f97fbc5ffd0>: Failed to establish a new connection: [Errno 61] Connection refused')': /session/dd68689530806d5cce215faad14b5f22
2024-03-27 03:12:48,770 [WARNING]: Retrying (Retry(total=0, connect=None, read=None, redirect=None, status=None)) after connection broken by 'NewConnectionError('<urllib3.connection.HTTPConnection object at 0x7f97fbba8fd0>: Failed to establish a new connection: [Errno 61] Connection refused')': /session/dd68689530806d5cce215faad14b5f22
2024-03-27 03:15:09,816 [INFO]: 2024-03-27 - 'Influencers_cases/test_login.py::Test_login::test_login_page' finished with outcome: passed
2024-03-27 03:15:22,675 [INFO]: 2024-03-27 - 'Influencers_cases/test_general_pages.py::Test_Home::test_influences_profile_setting' finished with outcome: passed
2024-03-27 03:15:43,014 [INFO]: 2024-03-27 - 'Influencers_cases/csdcnlsdknvtest_socail_pages.py::Test_Social::test_pinterest_author' finished with outcome: passed
2024-03-27 03:15:57,534 [INFO]: 2024-03-27 - 'Influencers_cases/csdcnlsdknvtest_socail_pages.py::Test_Social::test_facebook_author' finished with outcome: passed
2024-03-27 03:16:45,481 [ERROR]: 2024-03-27 - 'Influencers_cases/csdcnlsdknvtest_socail_pages.py::Test_Social::test_instagram_author' finished with outcome: failed
2024-03-27 03:16:47,026 [INFO]: 2024-03-27 - 'Influencers_cases/csdcnlsdknvtest_socail_pages.py::Test_Social::test_next_button' finished with outcome: passed
2024-03-27 03:16:59,320 [INFO]: 2024-03-27 - 'Influencers_cases/test_creator_details.py::Test_Creator::test_creator_details' finished with outcome: passed
2024-03-27 03:17:10,612 [INFO]: 2024-03-27 - 'Influencers_cases/test_compensation.py::Test_Compensation::test_compensation_details' finished with outcome: passed
2024-03-27 03:17:27,102 [INFO]: 2024-03-27 - 'Influencers_cases/test_capabilities.py::Test_Capabilities::test_capabilities_details' finished with outcome: passed
2024-03-27 03:17:45,735 [INFO]: 2024-03-27 - 'Influencers_cases/test_personal_details.py::Test_Personal::test_personal_details' finished with outcome: passed
2024-03-27 03:17:49,790 [WARNING]: Retrying (Retry(total=2, connect=None, read=None, redirect=None, status=None)) after connection broken by 'NewConnectionError('<urllib3.connection.HTTPConnection object at 0x7f9431f14550>: Failed to establish a new connection: [Errno 61] Connection refused')': /session/ecb9340d26111bda425a95dd5bd7193e
2024-03-27 03:17:49,791 [WARNING]: Retrying (Retry(total=1, connect=None, read=None, redirect=None, status=None)) after connection broken by 'NewConnectionError('<urllib3.connection.HTTPConnection object at 0x7f94324683a0>: Failed to establish a new connection: [Errno 61] Connection refused')': /session/ecb9340d26111bda425a95dd5bd7193e
2024-03-27 03:17:49,792 [WARNING]: Retrying (Retry(total=0, connect=None, read=None, redirect=None, status=None)) after connection broken by 'NewConnectionError('<urllib3.connection.HTTPConnection object at 0x7f9432383f40>: Failed to establish a new connection: [Errno 61] Connection refused')': /session/ecb9340d26111bda425a95dd5bd7193e
2024-03-27 03:18:25,367 [INFO]: 2024-03-27 - 'Influencers_cases/test_login.py::Test_login::test_login_page' finished with outcome: passed
2024-03-27 03:18:38,631 [INFO]: 2024-03-27 - 'Influencers_cases/test_general_pages.py::Test_Home::test_influences_profile_setting' finished with outcome: passed
2024-03-27 03:18:59,333 [INFO]: 2024-03-27 - 'Influencers_cases/csdcnlsdknvtest_socail_pages.py::Test_Social::test_pinterest_author' finished with outcome: passed
2024-03-27 03:19:04,754 [WARNING]: Retrying (Retry(total=2, connect=None, read=None, redirect=None, status=None)) after connection broken by 'NewConnectionError('<urllib3.connection.HTTPConnection object at 0x7fac4c89ba00>: Failed to establish a new connection: [Errno 61] Connection refused')': /session/130fbaa9eef5c789bf9d10471f1cc799
2024-03-27 03:19:04,755 [WARNING]: Retrying (Retry(total=1, connect=None, read=None, redirect=None, status=None)) after connection broken by 'NewConnectionError('<urllib3.connection.HTTPConnection object at 0x7fac4c89b640>: Failed to establish a new connection: [Errno 61] Connection refused')': /session/130fbaa9eef5c789bf9d10471f1cc799
2024-03-27 03:19:04,757 [WARNING]: Retrying (Retry(total=0, connect=None, read=None, redirect=None, status=None)) after connection broken by 'NewConnectionError('<urllib3.connection.HTTPConnection object at 0x7fac4c89b5e0>: Failed to establish a new connection: [Errno 61] Connection refused')': /session/130fbaa9eef5c789bf9d10471f1cc799
2024-03-27 03:23:00,630 [INFO]: 2024-03-27 - 'Influencers_cases/test_login.py::Test_login::test_login_page' finished with outcome: passed
2024-03-27 03:23:13,236 [INFO]: 2024-03-27 - 'Influencers_cases/test_general_pages.py::Test_Home::test_influences_profile_setting' finished with outcome: passed
2024-03-27 03:23:33,279 [INFO]: 2024-03-27 - 'Influencers_cases/csdcnlsdknvtest_socail_pages.py::Test_Social::test_pinterest_author' finished with outcome: passed
2024-03-27 03:23:46,716 [INFO]: 2024-03-27 - 'Influencers_cases/csdcnlsdknvtest_socail_pages.py::Test_Social::test_facebook_author' finished with outcome: passed
2024-03-27 03:24:34,747 [ERROR]: 2024-03-27 - 'Influencers_cases/csdcnlsdknvtest_socail_pages.py::Test_Social::test_instagram_author' finished with outcome: failed
2024-03-27 03:24:36,499 [INFO]: 2024-03-27 - 'Influencers_cases/csdcnlsdknvtest_socail_pages.py::Test_Social::test_next_button' finished with outcome: passed
2024-03-27 03:24:49,936 [INFO]: 2024-03-27 - 'Influencers_cases/test_creator_details.py::Test_Creator::test_creator_details' finished with outcome: passed
2024-03-27 03:25:00,190 [INFO]: 2024-03-27 - 'Influencers_cases/test_compensation.py::Test_Compensation::test_compensation_details' finished with outcome: passed
2024-03-27 03:25:16,987 [INFO]: 2024-03-27 - 'Influencers_cases/test_capabilities.py::Test_Capabilities::test_capabilities_details' finished with outcome: passed
2024-03-27 03:25:25,336 [INFO]: 2024-03-27 - 'Influencers_cases/test_personal_details.py::Test_Personal::test_personal_details' finished with outcome: passed
2024-03-27 03:25:48,687 [WARNING]: Retrying (Retry(total=2, connect=None, read=None, redirect=None, status=None)) after connection broken by 'NewConnectionError('<urllib3.connection.HTTPConnection object at 0x7f84666d3910>: Failed to establish a new connection: [Errno 61] Connection refused')': /session/68c36be2fa27df3f0a4fa39d163d3611
2024-03-27 03:25:48,688 [WARNING]: Retrying (Retry(total=1, connect=None, read=None, redirect=None, status=None)) after connection broken by 'NewConnectionError('<urllib3.connection.HTTPConnection object at 0x7f8466b95160>: Failed to establish a new connection: [Errno 61] Connection refused')': /session/68c36be2fa27df3f0a4fa39d163d3611
2024-03-27 03:25:48,689 [WARNING]: Retrying (Retry(total=0, connect=None, read=None, redirect=None, status=None)) after connection broken by 'NewConnectionError('<urllib3.connection.HTTPConnection object at 0x7f8466b0cfa0>: Failed to establish a new connection: [Errno 61] Connection refused')': /session/68c36be2fa27df3f0a4fa39d163d3611
2024-03-27 03:26:27,652 [INFO]: 2024-03-27 - 'Influencers_cases/test_login.py::Test_login::test_login_page' finished with outcome: passed
2024-03-27 03:26:40,071 [INFO]: 2024-03-27 - 'Influencers_cases/test_general_pages.py::Test_Home::test_influences_profile_setting' finished with outcome: passed
2024-03-27 03:26:59,804 [INFO]: 2024-03-27 - 'Influencers_cases/csdcnlsdknvtest_socail_pages.py::Test_Social::test_pinterest_author' finished with outcome: passed
2024-03-27 03:27:14,393 [INFO]: 2024-03-27 - 'Influencers_cases/csdcnlsdknvtest_socail_pages.py::Test_Social::test_facebook_author' finished with outcome: passed
2024-03-27 03:28:01,869 [ERROR]: 2024-03-27 - 'Influencers_cases/csdcnlsdknvtest_socail_pages.py::Test_Social::test_instagram_author' finished with outcome: failed
2024-03-27 03:28:03,731 [INFO]: 2024-03-27 - 'Influencers_cases/csdcnlsdknvtest_socail_pages.py::Test_Social::test_next_button' finished with outcome: passed
2024-03-27 03:28:15,671 [INFO]: 2024-03-27 - 'Influencers_cases/test_creator_details.py::Test_Creator::test_creator_details' finished with outcome: passed
2024-03-27 03:28:26,863 [INFO]: 2024-03-27 - 'Influencers_cases/test_compensation.py::Test_Compensation::test_compensation_details' finished with outcome: passed
2024-03-27 03:28:43,757 [INFO]: 2024-03-27 - 'Influencers_cases/test_capabilities.py::Test_Capabilities::test_capabilities_details' finished with outcome: passed
2024-03-27 03:28:51,064 [INFO]: 2024-03-27 - 'Influencers_cases/test_personal_details.py::Test_Personal::test_personal_details' finished with outcome: passed
2024-03-27 03:28:55,964 [WARNING]: Retrying (Retry(total=2, connect=None, read=None, redirect=None, status=None)) after connection broken by 'NewConnectionError('<urllib3.connection.HTTPConnection object at 0x7fb9525d5970>: Failed to establish a new connection: [Errno 61] Connection refused')': /session/868a1363d5ddd50af1819f956b748670
2024-03-27 03:28:55,965 [WARNING]: Retrying (Retry(total=1, connect=None, read=None, redirect=None, status=None)) after connection broken by 'NewConnectionError('<urllib3.connection.HTTPConnection object at 0x7fb9529e7280>: Failed to establish a new connection: [Errno 61] Connection refused')': /session/868a1363d5ddd50af1819f956b748670
2024-03-27 03:28:55,966 [WARNING]: Retrying (Retry(total=0, connect=None, read=None, redirect=None, status=None)) after connection broken by 'NewConnectionError('<urllib3.connection.HTTPConnection object at 0x7fb9529a5f10>: Failed to establish a new connection: [Errno 61] Connection refused')': /session/868a1363d5ddd50af1819f956b748670
2024-03-27 03:29:28,327 [INFO]: 2024-03-27 - 'Influencers_cases/test_signup.py::Test_Signup::test_random_email' finished with outcome: passed
2024-03-27 03:29:43,074 [INFO]: 2024-03-27 - 'Influencers_cases/test_signup.py::Test_Signup::test_form_child' finished with outcome: passed
2024-03-27 03:29:51,797 [INFO]: 2024-03-27 - 'Influencers_cases/test_signup.py::Test_Signup::test_verification_email' finished with outcome: passed
2024-03-27 03:30:13,742 [INFO]: 2024-03-27 - 'Influencers_cases/test_login.py::Test_login::test_login_page' finished with outcome: passed
2024-03-27 03:30:25,210 [INFO]: 2024-03-27 - 'Influencers_cases/test_general_pages.py::Test_Home::test_influences_profile_setting' finished with outcome: passed
2024-03-27 03:30:47,738 [INFO]: 2024-03-27 - 'Influencers_cases/csdcnlsdknvtest_socail_pages.py::Test_Social::test_pinterest_author' finished with outcome: passed
2024-03-27 03:31:03,154 [INFO]: 2024-03-27 - 'Influencers_cases/csdcnlsdknvtest_socail_pages.py::Test_Social::test_facebook_author' finished with outcome: passed
2024-03-27 03:31:50,896 [ERROR]: 2024-03-27 - 'Influencers_cases/csdcnlsdknvtest_socail_pages.py::Test_Social::test_instagram_author' finished with outcome: failed
2024-03-27 03:31:52,925 [INFO]: 2024-03-27 - 'Influencers_cases/csdcnlsdknvtest_socail_pages.py::Test_Social::test_next_button' finished with outcome: passed
2024-03-27 03:32:08,153 [INFO]: 2024-03-27 - 'Influencers_cases/test_creator_details.py::Test_Creator::test_creator_details' finished with outcome: passed
2024-03-27 03:32:19,511 [INFO]: 2024-03-27 - 'Influencers_cases/test_compensation.py::Test_Compensation::test_compensation_details' finished with outcome: passed
2024-03-27 03:32:36,858 [INFO]: 2024-03-27 - 'Influencers_cases/test_capabilities.py::Test_Capabilities::test_capabilities_details' finished with outcome: passed
2024-03-27 03:32:54,224 [ERROR]: 2024-03-27 - 'Influencers_cases/test_personal_details.py::Test_Personal::test_personal_details' finished with outcome: failed
2024-03-27 03:32:59,933 [WARNING]: Retrying (Retry(total=2, connect=None, read=None, redirect=None, status=None)) after connection broken by 'NewConnectionError('<urllib3.connection.HTTPConnection object at 0x7f77dd2e70d0>: Failed to establish a new connection: [Errno 61] Connection refused')': /session/d445d3f65104f9dc92f131f851319089
2024-03-27 03:32:59,936 [WARNING]: Retrying (Retry(total=1, connect=None, read=None, redirect=None, status=None)) after connection broken by 'NewConnectionError('<urllib3.connection.HTTPConnection object at 0x7f77dd2e7a90>: Failed to establish a new connection: [Errno 61] Connection refused')': /session/d445d3f65104f9dc92f131f851319089
2024-03-27 03:32:59,939 [WARNING]: Retrying (Retry(total=0, connect=None, read=None, redirect=None, status=None)) after connection broken by 'NewConnectionError('<urllib3.connection.HTTPConnection object at 0x7f77dc5d5d60>: Failed to establish a new connection: [Errno 61] Connection refused')': /session/d445d3f65104f9dc92f131f851319089
2024-03-27 03:35:36,610 [INFO]: 2024-03-27 - 'Influencers_cases/test_signup.py::Test_Signup::test_random_email' finished with outcome: passed
2024-03-27 03:36:06,610 [INFO]: 2024-03-27 - 'Influencers_cases/test_signup.py::Test_Signup::test_form_child' finished with outcome: passed
2024-03-27 03:36:18,886 [INFO]: 2024-03-27 - 'Influencers_cases/test_signup.py::Test_Signup::test_verification_email' finished with outcome: passed
2024-03-27 03:36:42,607 [INFO]: 2024-03-27 - 'Influencers_cases/test_login.py::Test_login::test_login_page' finished with outcome: passed
2024-03-27 03:36:58,332 [INFO]: 2024-03-27 - 'Influencers_cases/test_general_pages.py::Test_Home::test_influences_profile_setting' finished with outcome: passed
2024-03-27 03:37:25,701 [INFO]: 2024-03-27 - 'Influencers_cases/csdcnlsdknvtest_socail_pages.py::Test_Social::test_pinterest_author' finished with outcome: passed
2024-03-27 03:37:40,801 [INFO]: 2024-03-27 - 'Influencers_cases/csdcnlsdknvtest_socail_pages.py::Test_Social::test_facebook_author' finished with outcome: passed
2024-03-27 03:38:29,568 [ERROR]: 2024-03-27 - 'Influencers_cases/csdcnlsdknvtest_socail_pages.py::Test_Social::test_instagram_author' finished with outcome: failed
2024-03-27 03:38:32,179 [INFO]: 2024-03-27 - 'Influencers_cases/csdcnlsdknvtest_socail_pages.py::Test_Social::test_next_button' finished with outcome: passed
2024-03-27 03:38:50,403 [INFO]: 2024-03-27 - 'Influencers_cases/test_creator_details.py::Test_Creator::test_creator_details' finished with outcome: passed
2024-03-27 03:39:02,251 [INFO]: 2024-03-27 - 'Influencers_cases/test_compensation.py::Test_Compensation::test_compensation_details' finished with outcome: passed
2024-03-27 03:39:18,947 [INFO]: 2024-03-27 - 'Influencers_cases/test_capabilities.py::Test_Capabilities::test_capabilities_details' finished with outcome: passed
2024-03-27 03:39:39,394 [ERROR]: 2024-03-27 - 'Influencers_cases/test_personal_details.py::Test_Personal::test_personal_details' finished with outcome: failed
2024-03-27 03:39:43,671 [WARNING]: Retrying (Retry(total=2, connect=None, read=None, redirect=None, status=None)) after connection broken by 'NewConnectionError('<urllib3.connection.HTTPConnection object at 0x7fa7f1c8d760>: Failed to establish a new connection: [Errno 61] Connection refused')': /session/0e926776e24d469f7c69cc82e4b99404
2024-03-27 03:39:43,674 [WARNING]: Retrying (Retry(total=1, connect=None, read=None, redirect=None, status=None)) after connection broken by 'NewConnectionError('<urllib3.connection.HTTPConnection object at 0x7fa7f1c8d100>: Failed to establish a new connection: [Errno 61] Connection refused')': /session/0e926776e24d469f7c69cc82e4b99404
2024-03-27 03:39:43,676 [WARNING]: Retrying (Retry(total=0, connect=None, read=None, redirect=None, status=None)) after connection broken by 'NewConnectionError('<urllib3.connection.HTTPConnection object at 0x7fa7f1c8d910>: Failed to establish a new connection: [Errno 61] Connection refused')': /session/0e926776e24d469f7c69cc82e4b99404
2024-03-27 03:41:40,771 [INFO]: 2024-03-27 - 'Influencers_cases/test_signup.py::Test_Signup::test_random_email' finished with outcome: passed
2024-03-27 03:42:03,733 [ERROR]: 2024-03-27 - 'Influencers_cases/test_signup.py::Test_Signup::test_form_child' finished with outcome: failed
2024-03-27 03:42:13,648 [WARNING]: Retrying (Retry(total=2, connect=None, read=None, redirect=None, status=None)) after connection broken by 'NewConnectionError('<urllib3.connection.HTTPConnection object at 0x7f9980ae31c0>: Failed to establish a new connection: [Errno 61] Connection refused')': /session/988a8a165f8a196445a78a45a9afc770
2024-03-27 03:42:13,652 [WARNING]: Retrying (Retry(total=1, connect=None, read=None, redirect=None, status=None)) after connection broken by 'NewConnectionError('<urllib3.connection.HTTPConnection object at 0x7f9980ae3070>: Failed to establish a new connection: [Errno 61] Connection refused')': /session/988a8a165f8a196445a78a45a9afc770
2024-03-27 03:42:13,654 [WARNING]: Retrying (Retry(total=0, connect=None, read=None, redirect=None, status=None)) after connection broken by 'NewConnectionError('<urllib3.connection.HTTPConnection object at 0x7f997db47460>: Failed to establish a new connection: [Errno 61] Connection refused')': /session/988a8a165f8a196445a78a45a9afc770
2024-03-27 03:42:36,126 [INFO]: 2024-03-27 - 'Influencers_cases/test_signup.py::Test_Signup::test_random_email' finished with outcome: passed
2024-03-27 03:43:01,354 [INFO]: 2024-03-27 - 'Influencers_cases/test_signup.py::Test_Signup::test_form_child' finished with outcome: passed
2024-03-27 03:43:13,214 [INFO]: 2024-03-27 - 'Influencers_cases/test_signup.py::Test_Signup::test_verification_email' finished with outcome: passed
2024-03-27 03:43:36,671 [INFO]: 2024-03-27 - 'Influencers_cases/test_login.py::Test_login::test_login_page' finished with outcome: passed
2024-03-27 03:43:51,269 [INFO]: 2024-03-27 - 'Influencers_cases/test_general_pages.py::Test_Home::test_influences_profile_setting' finished with outcome: passed
2024-03-27 03:44:18,214 [INFO]: 2024-03-27 - 'Influencers_cases/csdcnlsdknvtest_socail_pages.py::Test_Social::test_pinterest_author' finished with outcome: passed
2024-03-27 03:44:33,489 [INFO]: 2024-03-27 - 'Influencers_cases/csdcnlsdknvtest_socail_pages.py::Test_Social::test_facebook_author' finished with outcome: passed
2024-03-27 03:45:25,309 [ERROR]: 2024-03-27 - 'Influencers_cases/csdcnlsdknvtest_socail_pages.py::Test_Social::test_instagram_author' finished with outcome: failed
2024-03-27 03:45:28,115 [INFO]: 2024-03-27 - 'Influencers_cases/csdcnlsdknvtest_socail_pages.py::Test_Social::test_next_button' finished with outcome: passed
2024-03-27 03:46:29,472 [INFO]: 2024-03-27 - 'Influencers_cases/test_creator_details.py::Test_Creator::test_creator_details' finished with outcome: passed
2024-03-27 03:46:40,917 [INFO]: 2024-03-27 - 'Influencers_cases/test_compensation.py::Test_Compensation::test_compensation_details' finished with outcome: passed
2024-03-27 03:46:58,290 [INFO]: 2024-03-27 - 'Influencers_cases/test_capabilities.py::Test_Capabilities::test_capabilities_details' finished with outcome: passed
2024-03-27 03:47:15,665 [ERROR]: 2024-03-27 - 'Influencers_cases/test_personal_details.py::Test_Personal::test_personal_details' finished with outcome: failed
2024-03-27 03:47:20,762 [WARNING]: Retrying (Retry(total=2, connect=None, read=None, redirect=None, status=None)) after connection broken by 'NewConnectionError('<urllib3.connection.HTTPConnection object at 0x7fde566fa7c0>: Failed to establish a new connection: [Errno 61] Connection refused')': /session/08ad0e8b50c39a8a6b02e4160bb93c3a
2024-03-27 03:47:20,766 [WARNING]: Retrying (Retry(total=1, connect=None, read=None, redirect=None, status=None)) after connection broken by 'NewConnectionError('<urllib3.connection.HTTPConnection object at 0x7fde546f83d0>: Failed to establish a new connection: [Errno 61] Connection refused')': /session/08ad0e8b50c39a8a6b02e4160bb93c3a
2024-03-27 03:47:20,770 [WARNING]: Retrying (Retry(total=0, connect=None, read=None, redirect=None, status=None)) after connection broken by 'NewConnectionError('<urllib3.connection.HTTPConnection object at 0x7fde56b55d90>: Failed to establish a new connection: [Errno 61] Connection refused')': /session/08ad0e8b50c39a8a6b02e4160bb93c3a
2024-03-27 03:51:33,035 [INFO]: 2024-03-27 - 'Influencers_cases/test_signup.py::Test_Signup::test_random_email' finished with outcome: passed
2024-03-27 03:51:56,394 [INFO]: 2024-03-27 - 'Influencers_cases/test_signup.py::Test_Signup::test_form_child' finished with outcome: passed
2024-03-27 03:52:12,991 [INFO]: 2024-03-27 - 'Influencers_cases/test_signup.py::Test_Signup::test_verification_email' finished with outcome: passed
2024-03-27 03:52:41,925 [INFO]: 2024-03-27 - 'Influencers_cases/test_login.py::Test_login::test_login_page' finished with outcome: passed
2024-03-27 03:52:59,233 [INFO]: 2024-03-27 - 'Influencers_cases/test_general_pages.py::Test_Home::test_influences_profile_setting' finished with outcome: passed
2024-03-27 03:53:30,113 [INFO]: 2024-03-27 - 'Influencers_cases/csdcnlsdknvtest_socail_pages.py::Test_Social::test_pinterest_author' finished with outcome: passed
2024-03-27 03:53:44,893 [INFO]: 2024-03-27 - 'Influencers_cases/csdcnlsdknvtest_socail_pages.py::Test_Social::test_facebook_author' finished with outcome: passed
2024-03-27 03:54:34,860 [ERROR]: 2024-03-27 - 'Influencers_cases/csdcnlsdknvtest_socail_pages.py::Test_Social::test_instagram_author' finished with outcome: failed
2024-03-27 03:54:37,924 [INFO]: 2024-03-27 - 'Influencers_cases/csdcnlsdknvtest_socail_pages.py::Test_Social::test_next_button' finished with outcome: passed
2024-03-27 03:54:56,091 [INFO]: 2024-03-27 - 'Influencers_cases/test_creator_details.py::Test_Creator::test_creator_details' finished with outcome: passed
2024-03-27 03:55:07,934 [INFO]: 2024-03-27 - 'Influencers_cases/test_compensation.py::Test_Compensation::test_compensation_details' finished with outcome: passed
2024-03-27 03:55:25,325 [INFO]: 2024-03-27 - 'Influencers_cases/test_capabilities.py::Test_Capabilities::test_capabilities_details' finished with outcome: passed
2024-03-27 03:55:37,482 [WARNING]: Retrying (Retry(total=2, connect=None, read=None, redirect=None, status=None)) after connection broken by 'NewConnectionError('<urllib3.connection.HTTPConnection object at 0x7fc9da7388e0>: Failed to establish a new connection: [Errno 61] Connection refused')': /session/87771961e0abf8fca81cdf21334b297e
2024-03-27 03:55:37,484 [WARNING]: Retrying (Retry(total=1, connect=None, read=None, redirect=None, status=None)) after connection broken by 'NewConnectionError('<urllib3.connection.HTTPConnection object at 0x7fc9daabbaf0>: Failed to establish a new connection: [Errno 61] Connection refused')': /session/87771961e0abf8fca81cdf21334b297e
2024-03-27 03:55:37,486 [WARNING]: Retrying (Retry(total=0, connect=None, read=None, redirect=None, status=None)) after connection broken by 'NewConnectionError('<urllib3.connection.HTTPConnection object at 0x7fc9daabefa0>: Failed to establish a new connection: [Errno 61] Connection refused')': /session/87771961e0abf8fca81cdf21334b297e
2024-03-27 03:59:30,108 [INFO]: 2024-03-27 - 'Influencers_cases/test_signup.py::Test_Signup::test_random_email' finished with outcome: passed
2024-03-27 03:59:46,269 [INFO]: 2024-03-27 - 'Influencers_cases/test_signup.py::Test_Signup::test_form_child' finished with outcome: passed
2024-03-27 03:59:51,841 [INFO]: 2024-03-27 - 'Influencers_cases/test_signup.py::Test_Signup::test_verification_email' finished with outcome: passed
2024-03-27 04:00:11,834 [INFO]: 2024-03-27 - 'Influencers_cases/test_login.py::Test_login::test_login_page' finished with outcome: passed
2024-03-27 04:00:23,643 [INFO]: 2024-03-27 - 'Influencers_cases/test_general_pages.py::Test_Home::test_influences_profile_setting' finished with outcome: passed
2024-03-27 04:00:43,701 [INFO]: 2024-03-27 - 'Influencers_cases/csdcnlsdknvtest_socail_pages.py::Test_Social::test_pinterest_author' finished with outcome: passed
2024-03-27 04:00:57,543 [INFO]: 2024-03-27 - 'Influencers_cases/csdcnlsdknvtest_socail_pages.py::Test_Social::test_facebook_author' finished with outcome: passed
2024-03-27 04:01:43,530 [ERROR]: 2024-03-27 - 'Influencers_cases/csdcnlsdknvtest_socail_pages.py::Test_Social::test_instagram_author' finished with outcome: failed
2024-03-27 04:01:45,164 [INFO]: 2024-03-27 - 'Influencers_cases/csdcnlsdknvtest_socail_pages.py::Test_Social::test_next_button' finished with outcome: passed
2024-03-27 04:01:58,078 [INFO]: 2024-03-27 - 'Influencers_cases/test_creator_details.py::Test_Creator::test_creator_details' finished with outcome: passed
2024-03-27 04:02:09,247 [INFO]: 2024-03-27 - 'Influencers_cases/test_compensation.py::Test_Compensation::test_compensation_details' finished with outcome: passed
2024-03-27 04:02:25,127 [INFO]: 2024-03-27 - 'Influencers_cases/test_capabilities.py::Test_Capabilities::test_capabilities_details' finished with outcome: passed
2024-03-27 04:02:34,516 [INFO]: 2024-03-27 - 'Influencers_cases/test_personal_details.py::Test_Personal::test_personal_details' finished with outcome: passed
2024-03-27 04:02:45,505 [WARNING]: Retrying (Retry(total=2, connect=None, read=None, redirect=None, status=None)) after connection broken by 'NewConnectionError('<urllib3.connection.HTTPConnection object at 0x7fdbd0f388b0>: Failed to establish a new connection: [Errno 61] Connection refused')': /session/e8845187da5ed0e63899c966c130d3b2
2024-03-27 04:02:45,507 [WARNING]: Retrying (Retry(total=1, connect=None, read=None, redirect=None, status=None)) after connection broken by 'NewConnectionError('<urllib3.connection.HTTPConnection object at 0x7fdbd1f8c5b0>: Failed to establish a new connection: [Errno 61] Connection refused')': /session/e8845187da5ed0e63899c966c130d3b2
2024-03-27 04:02:45,508 [WARNING]: Retrying (Retry(total=0, connect=None, read=None, redirect=None, status=None)) after connection broken by 'NewConnectionError('<urllib3.connection.HTTPConnection object at 0x7fdbd1f8cac0>: Failed to establish a new connection: [Errno 61] Connection refused')': /session/e8845187da5ed0e63899c966c130d3b2
2024-03-27 04:04:09,505 [ERROR]: 2024-03-27 - 'Influencers_cases/test_login.py::Test_login::test_login_page' finished with outcome: failed
2024-03-27 04:04:13,528 [ERROR]: 2024-03-27 - 'Influencers_cases/test_general_pages.py::Test_Home::test_influences_profile_setting' finished with outcome: failed
2024-03-27 04:04:33,447 [WARNING]: Retrying (Retry(total=2, connect=None, read=None, redirect=None, status=None)) after connection broken by 'NewConnectionError('<urllib3.connection.HTTPConnection object at 0x7f94ac7112b0>: Failed to establish a new connection: [Errno 61] Connection refused')': /session/e14d2202bac296e7e1c31d2a7924112f
2024-03-27 04:04:33,448 [WARNING]: Retrying (Retry(total=1, connect=None, read=None, redirect=None, status=None)) after connection broken by 'NewConnectionError('<urllib3.connection.HTTPConnection object at 0x7f94acb2c0d0>: Failed to establish a new connection: [Errno 61] Connection refused')': /session/e14d2202bac296e7e1c31d2a7924112f
2024-03-27 04:04:33,449 [WARNING]: Retrying (Retry(total=0, connect=None, read=None, redirect=None, status=None)) after connection broken by 'NewConnectionError('<urllib3.connection.HTTPConnection object at 0x7f94acb13e20>: Failed to establish a new connection: [Errno 61] Connection refused')': /session/e14d2202bac296e7e1c31d2a7924112f
2024-03-27 04:05:13,584 [ERROR]: 2024-03-27 - 'Influencers_cases/test_login.py::Test_login::test_login_page' finished with outcome: failed
2024-03-27 04:05:17,592 [ERROR]: 2024-03-27 - 'Influencers_cases/test_general_pages.py::Test_Home::test_influences_profile_setting' finished with outcome: failed
2024-03-27 04:05:48,928 [ERROR]: 2024-03-27 - 'Influencers_cases/csdcnlsdknvtest_socail_pages.py::Test_Social::test_pinterest_author' finished with outcome: failed
2024-03-27 04:06:07,037 [WARNING]: Retrying (Retry(total=2, connect=None, read=None, redirect=None, status=None)) after connection broken by 'NewConnectionError('<urllib3.connection.HTTPConnection object at 0x7fbbdded1520>: Failed to establish a new connection: [Errno 61] Connection refused')': /session/e67a3d1e377b6135dd32015b9868668c
2024-03-27 04:06:07,038 [WARNING]: Retrying (Retry(total=1, connect=None, read=None, redirect=None, status=None)) after connection broken by 'NewConnectionError('<urllib3.connection.HTTPConnection object at 0x7fbbdb4a1eb0>: Failed to establish a new connection: [Errno 61] Connection refused')': /session/e67a3d1e377b6135dd32015b9868668c
2024-03-27 04:06:07,039 [WARNING]: Retrying (Retry(total=0, connect=None, read=None, redirect=None, status=None)) after connection broken by 'NewConnectionError('<urllib3.connection.HTTPConnection object at 0x7fbbdb4a1d00>: Failed to establish a new connection: [Errno 61] Connection refused')': /session/e67a3d1e377b6135dd32015b9868668c
2024-03-27 04:06:51,776 [INFO]: 2024-03-27 - 'Influencers_cases/test_login.py::Test_login::test_login_page' finished with outcome: passed
2024-03-27 04:07:06,332 [INFO]: 2024-03-27 - 'Influencers_cases/test_general_pages.py::Test_Home::test_influences_profile_setting' finished with outcome: passed
2024-03-27 04:07:29,895 [INFO]: 2024-03-27 - 'Influencers_cases/csdcnlsdknvtest_socail_pages.py::Test_Social::test_pinterest_author' finished with outcome: passed
2024-03-27 04:07:45,800 [INFO]: 2024-03-27 - 'Influencers_cases/csdcnlsdknvtest_socail_pages.py::Test_Social::test_facebook_author' finished with outcome: passed
2024-03-27 04:08:34,729 [ERROR]: 2024-03-27 - 'Influencers_cases/csdcnlsdknvtest_socail_pages.py::Test_Social::test_instagram_author' finished with outcome: failed
2024-03-27 04:08:37,038 [INFO]: 2024-03-27 - 'Influencers_cases/csdcnlsdknvtest_socail_pages.py::Test_Social::test_next_button' finished with outcome: passed
2024-03-27 04:08:51,805 [INFO]: 2024-03-27 - 'Influencers_cases/test_creator_details.py::Test_Creator::test_creator_details' finished with outcome: passed
2024-03-27 04:09:03,536 [INFO]: 2024-03-27 - 'Influencers_cases/test_compensation.py::Test_Compensation::test_compensation_details' finished with outcome: passed
2024-03-27 04:09:20,939 [INFO]: 2024-03-27 - 'Influencers_cases/test_capabilities.py::Test_Capabilities::test_capabilities_details' finished with outcome: passed
2024-03-27 04:09:29,388 [INFO]: 2024-03-27 - 'Influencers_cases/test_personal_details.py::Test_Personal::test_personal_details' finished with outcome: passed
2024-03-27 04:09:39,236 [WARNING]: Retrying (Retry(total=2, connect=None, read=None, redirect=None, status=None)) after connection broken by 'NewConnectionError('<urllib3.connection.HTTPConnection object at 0x7fdf0f6d2820>: Failed to establish a new connection: [Errno 61] Connection refused')': /session/6f91fb4539ab6d3a761411f967386427
2024-03-27 04:09:39,238 [WARNING]: Retrying (Retry(total=1, connect=None, read=None, redirect=None, status=None)) after connection broken by 'NewConnectionError('<urllib3.connection.HTTPConnection object at 0x7fdf0fb49940>: Failed to establish a new connection: [Errno 61] Connection refused')': /session/6f91fb4539ab6d3a761411f967386427
2024-03-27 04:09:39,241 [WARNING]: Retrying (Retry(total=0, connect=None, read=None, redirect=None, status=None)) after connection broken by 'NewConnectionError('<urllib3.connection.HTTPConnection object at 0x7fdf0cc27250>: Failed to establish a new connection: [Errno 61] Connection refused')': /session/6f91fb4539ab6d3a761411f967386427
